Workbook
Name a: #REF!
Name AAA: #REF!
Name ATICA_DATA: #REF!
Name CAPE_DATA: #REF!
Name DicoRefFOTibco: #REF!
Name Field_Data_Types: #REF!
Name ListeMsg: #REF!
Name ListeMsg: #REF!
Name ListeMsg: #REF!
Name ListeTypeEntite: #REF!
Name Name: #REF!
Name TOTO: #REF!
Name ZoneDicoRefFO: #REF!
Name ZoneDicoRefFO: #REF!
Name ZoneDicoRefFO: #REF!

Sheet ChangeLog
A1: Version | B1: Auteur | C1: Date | D1: Domaine | E1: Description | F1: Origine
A2: 21.17 | B2: G.HARAGHI | C2: 46180 | D2: Acquisition | E2: Pour la donnée (250827114300): changement du libellé :"These messages are file action instructions (0360)." ==> "Number of messages in the file - File action instructions - 360" + Changement du mapping + Changement de type de "Max6NumericText" devient "Max10NumericText" Pour la donnée (250827114500): Changement du libellé "The number of messages that the file sender" ==> "Number of messages that the file sender can transmit without waiting for an acknowledgement message (0370)" + changement du mapping Pour la donnée (250827113500): Changement du mapping Pour la donnée (250827114100): Changement du mapping La donnée(250604103001) a été rendue obsolète La donnée (260605091000) qui est en doublon a été supprimée
A3: 21.17 | B3: B. Porcher | C3: 46181 | D3: Acquisition | E3: Creation de la donnée reservedUseData : 260608100200 // Transaction // transactionDetails // reservedUseData // ReservedUseDataType // DNS // // Data and structure usable for reserved field | F3: BK-9845
A4: 21.17 | B4: B. Porcher | C4: 46181 | D4: Acquisition | E4: Creation de la structure ReservedUseDataType: ReservedUseDataType // complement // Max255Text // Information on the reserved use data ReservedUseDataType // typeData // Max50Text // Name of the reserved use data ReservedUseDataType // value // Max3000Text // Value of the reserved use data | F4: BK-9845
A5: 21.16 | B5: G.HARAGHI | C5: 46178 | D5: Acquisition | E5: Modification d'attribut: 260310134700 \\ Header \\ headerFunctionalInfo \\ V \\ UUIDType \\ DNS \\ Id created for each transaction to associate nativ and Estreem format data. ==> 260310134700 \\ Header \\ headerFunctionalInfo \\ transactionCorrelationId \\ UUIDType \\ DNS \\ Id created for each transaction to associate native and Processor format data. | F5: Message de Luc
A6: 21.16 | B6: G.HARAGHI | C6: 46178 | D6: Acquisition | E6: Création d'attributs: fileData \\ captureFileReceivedDateTime \\ ISODateTime \\ DNS \\ File reception date calculated by capture fileData \\ captureErrorSequenceNumberOfMessage \\ Max10NumericText \\ DNS \\ Sequence number of the relevant message in the file fileData \\ fileNumberOfMessages \\ Max10NumericText \\ DNS \\ Number of message in the file Modification du codeset CardholderPresenceCodeset: Remplacer le valeur VADS par SERT = Secure Remote Transaction Modification d'attributs: 260310134700 \\ Header \\ headerFunctionalInfo \\ transactionDataCorrelationId \\ UUIDType \\ DNS \\ Id created for each transaction to associate nativ and Estreem format data. ==> 260310134700 \\ Header \\ headerFunctionalInfo \\ transactionCorrelationId \\ UUIDType \\ DNS \\ Id created for each transaction to associate nativ and Estreem format data. | F6: BK-9975
A7: 21.16 | B7: G.HARAGHI | C7: 46177 | D7: Acquisition | E7: Modification du codeset: IcsSettlementServiceCodeset Ajout des valeurs: IcsSettlementServiceCodeset \\ Exact4Text \\ WSAL \\ Mastercard Wholesale Settlement Service IcsSettlementServiceCodeset \\ Exact4Text \\ TRGT \\ Cartes bancaires TARGET2 Settlement Service | F7: BK-9970
A8: 21.16 | B8: G.HARAGHI | C8: 46176 | D8: Acquisition | E8: Modification de l'attribut: 250528140503 \\ Context \\ transactionContext \\ princingEngineDesignation \\ Max200Text \\ DNS \\ Textual description of transaction nature with country, region, network, .. ==> 250528140503 \\ Context \\ transactionContext \\ qualificationDesignation \\ Max200Text \\ DNS \\ Textual description of transaction nature with country, region, network, .. | F8: BK-9968
A9: 21.15 | C9: 45806 | D9: Emission | E9: Modification d'attribut: 260424190700 // Environment // cardTariff // calculationMethod // CardFeeCalculationMethodCodeset // DNS // Method used to calculate the card fee ==> 260424190700 // Environment // cardFee // calculationMethod // CardFeeCalculationMethodCodeset // DNS // Method used to calculate the card fee Création d'attribut: 260529115100 // Environment // cardTariff // calculationMethod // CardFeeCalculationMethodCodeset // DNS // Method used to calculate the card fee | F9: Coquille(BK-9903)
A10: 21.15 | B10: G.HARAGHI | C10: 45806 | D10: Emission | E10: Modification d'arttribut: 260518102400 \\ Environment \\ cardTariff \\ negociatedTariffStartDate \\ ISODate \\ DNS \\ Start date of the period of a negotiated tariff ==> 260518102400 \\ Environment \\ cardTariff \\ negotiatedTariffStartDate \\ ISODate \\ DNS \\ Start date of the period of a negotiated tariff 260518102600 \\ Environment \\ cardTariff \\ negociatedTariffEndDate \\ ISODate \\ DNS \\ End date of the period of a negotiated tariff ==> 260518102600 \\ Environment \\ cardTariff \\ negotiatedTariffEndDate \\ ISODate \\ DNS \\ End date of the period of a negotiated tariff | F10: Message de Luc
A11: 21.15 | B11: G.HARAGHI | C11: 46171 | D11: Emission | E11: Modification d'attribut: 260518105700 \\ Environment \\ cardTariff \\ discountRate \\ FeeAmountType \\ DNS \\ Discount applied on the standard tariff ==> 260518105700 \\ Environment \\ cardTariff \\ discountRate \\ PercentageRate \\ DNS \\ Discount applied on the standard tariff | F11: Coquille(BK-9903)
A12: 21.15 | B12: G.HARAGHI | C12: 46170 | D12: Contestation | E12: Modification des valeurs prises par le codeset RefundNatureCodeset : Retirer BCFI et ESTR Ajouter PROC : Processor Ajouter ESFI : Establishment financing Modification d'attribut: 260526111400 \\ AuditTrail \\ auditTrail \\ walletEnrolmentAuthenticationMean \\ AuthenticationMethodCodeset \\ DNS \\ Indicates the technical method of strong authentication used during the card enrolment into the digital wallet ==> 260526111400 \\ AuditTrail \\ auditTrail \\ walletEnrolmentAuthenticationMethod \\ AuthenticationMethodCodeset \\ DNS \\ Indicates the technical method of strong authentication used during the card enrolment into the digital wallet
A13: 21.15 | B13: G.HARAGHI | C13: 46170 | D13: Contestation | E13: Modification d'attribut: 260526131700 \\ Edition \\ editionParameters \\ mailVariant \\ Max2Text \\ DNS \\ Defines the letter variant to be generated and allows adapting the layout and document subject ==> 260526131700 \\ Edition \\ editionParameters \\ variant \\ Max2Text \\ DNS \\ Defines the letter variant to be generated and allows adapting the layout and document subject 260422142700 \\ Edition \\ editionParameters \\ mailRequestDateTime \\ ISODateTime \\ DNS \\ Letter request date time ==> 260422142700 \\ Edition \\ editionParameters \\ requestDateTime \\ ISODateTime \\ DNS \\ Letter request date time | F13: BK-9955
A14: 21.15 | B14: G.HARAGHI | C14: 46170 | D14: Contestation | E14: Création d'attributs: 260528140500 \\ Edition \\ editionParameters \\ annexTableName \\ Max50Text \\ DNS \\ Name of the table annex 260528140700 \\ Edition \\ editionParameters \\ annexTableColumn \\ Max50Text \\ DNS \\ Column of the table annex 260528140800 \\ Edition \\ editionParameters \\ annexTableData \\ Max50Text \\ DNS \\ Data of the table annex 260528142000 \\ Transaction threeDs threeDSAuthenticationDateTime \\ ISODateTime \\ DNS \\ Date and time of the authentication Modification des valeurs prises par le codeset DisputeQualificationCodeset : LITC : Dispute - Commercial -> DCOM : Dispute - Commercial Suppression des champs: 260526110400 \\ Context \\ transactionContext \\ processorCode \\ NetworkCodeset \\ DNS \\Code identifying the transaction processing channel (internal or external network), derived from INTRA/ON-US indicator, card network, and operation type. 260526112000 \\ AuditTrail \\ auditTrail \\ acsAuthenticationDateTime \\ ISODateTime \\ DNS \\ Date and time of the transaction authentication | F14: BK-9954
A15: 21.15 | B15: G.HARAGHI | C15: 46168 | D15: Contestation | E15: Creation de codeset: WalletEnrolmentChannelCodeset WalletEnrolmentChannelCodeset \\ Exact4Text \\ APBA \\ enrolment from the banking application WalletEnrolmentChannelCodeset \\ Exact4Text \\ APWA \\ enrolment from the wallet application Création du codeset: AuthenticationEnrolmentChannelCodeset AuthenticationEnrolmentChannelCodeset \\ Exact4Text \\ INAP \\ In-App Banking AuthenticationEnrolmentChannelCodeset \\ Exact4Text \\ WEBB \\ Web Banking AuthenticationEnrolmentChannelCodeset \\ Exact4Text \\ CALL \\ Call Center AuthenticationEnrolmentChannelCodeset \\ Exact4Text \\ MAIL \\ Postal Mail AuthenticationEnrolmentChannelCodeset \\ Exact4Text \\ OTHR \\ Other | F15: BK-9914
A16: 21.15 | B16: G.HARAGHI | C16: 46168 | D16: Contestation | E16: Modification Codeset: RefundNatureCodeset Retirer NTXS : Natixis Ajouter ESTR : ESTREEM Modification Codeset: DisputeQualificationCodeset Modification des valeurs prises par le codeset DisputeQualificationCodeset : OPME : Operation wrongly executed. -> OPWE : Operation wrongly executed. Modification Codeset: DisputeConditionCodeset Modification des valeurs prises par le codeset DisputeConditionCodeset : CAEC : Expired card -> CAEX : Expired card CCLO : Closed Account -> ACLO : Closed Account CEAM : Card extorted with threats -> CEWT : Card extorted with threats CNPA : Card not delivered to the cardholder -> CNDL : Card not delivered to the cardholder COPP : Suspended card -> CSUS : Suspended card CPER : Lost Card -> CLST : Lost Card CVSV : Stolen card without violence -> SCWV : Stolen card without violence DEMA : Defect in merchandise/service -> DEMS : Defect in merchandise/service DETC : Account jacking -> AJAC : Account jacking DOUB : Duplicate processing -> DUPL : Duplicate processing FCTC : Disputed invoice -> DINV : Disputed invoice FRDF : Differed fee -> DIFF : Differed fee MOER : Incorrect amount -> INAM : Incorrect amount PRIN : Non-existant cardholder -> NEXC : Non-existant cardholder RFPM : DDJ MC -> RFPM : Request for proof MC RFPV : DDJ VISA -> RFPV : Request for proof VISA RNDI : Undistributed withdrawal -> UNWD : Undistributed withdrawal RPAR : issuer ATM regulation before claim -> ARBC : issuer ATM regulation before claim RPDI : Partially distributed withdrawal -> PDWD : Partially distributed withdrawal Modification Codeset: WalletProviderCodeset Ajout des valeurs prises par le codeset WalletProviderCodeset : WPAY : Wero Pay OPAY : Open Payment | F16: BK-9914
A17: 21.15 | B17: G.HARAGHI | C17: 46168 | D17: Contestation | E17: Modification d'attributs: 250617101500 \\ Transaction \\ chargebackData \\ additionalData \\ AdditionalDataType \\ DNS \\ Additionnal data ==> 250617101500 \\ Transaction \\ chargebackData \\ additionalData \\ AdditionalDataType \\ DNS \\ Additional data 251027112335 \\ Context \\ crcCase \\ additionnalData \\ AdditionalDataType \\ DNS \\ Additionnal Data ==> 251027112335 \\ Context \\ crcCase \\ additionalData \\ AdditionalDataType \\ DNS \\ Additional Data 260422141000 \\ Transaction claimData \\ additionnalData \\ AdditionalDataType \\ DNS \\ Additionnal Data ==> 260422141000 \\ Transaction \\ claimData \\ additionalData \\ AdditionalDataType \\ DNS \\ Additional Data 250324131105 \\ Transaction \\ disputeData \\ additionnalData \\ TrueFalseIndicator \\ DNS \\ Additionnal data ==> 250324131105 \\ Transaction \\ disputeData \\ additionalData \\ TrueFalseIndicator \\ DNS \\ Additional data 250528104039 \\ AuditTrail \\ auditTrail \\ deviceTechnicalName \\ Max255Text \\ DNS \\ Enrolment terminal ==> 250528104039 \\ AuditTrail \\ auditTrail \\ deviceTechnicalName \\ Max255Text \\ DNS Technical name of the device 250717102632 \\ Environment \\ terminal \\ enrolmentCity \\ Max70Text \\ DNS \\ City of enrolment ==> 250717102632 \\ Environment \\ terminal \\ city \\ Max70Text \\ DNS \\ City associated with the device | F17: BK-9914
A18: 21.15 | B18: G.HARAGHI | C18: 46168 | D18: Contestation | E18: Création d'attributs: 260526110000 \\ Edition editionParameters \\ requestDateTime \\ ISODateTime \\ DNS \\ Edition request date time 260526110400 \\ Context \\ transactionContex t\\ processorCode \\ NetworkCodeset \\ DNS \\ Code identifying the transaction processing channel (internal or external network), derived from INTRA/ON-US indicator, card network, and operation type. 260526110800 \\ AuditTrail \\ auditTrail\\ walletEnrolmentChannel \\ WalletEnrolmentChannelCodeset \\ DNS \\ Indicates the channel through which the card was enrolled into the digital wallet. 260526111000 \\ AuditTrail \\ auditTrail\\ walletEnrolmentAuthenticationMean \\ AuthenticationMeanCodeset \\ DNS \\ Strong authentication method used for the enrolment of the card into a digital wallet 260526111200 \\ AuditTrail \\ auditTrail\\ walletEnrolmentDateTime \\ ISODateTime \\ DNS \\ Date and time when the card was enrolled into the digital wallet 260526111400 \\ AuditTrail \\ auditTrail\\ walletEnrolmentAuthenticationMean \\ AuthenticationMethodCodeset \\ DNS \\ Indicates the technical method of strong authentication used during the card enrolment into the digital wallet 260526111600 \\ AuditTrail \\ auditTrail\\ walletEnrolmentAuthenticationSuccessfulIndicator \\ TrueFalseIndicator \\ DNS \\ Indicates whether the strong authentication process for the card enrollment into the digital wallet was completed successfully 260526111800 \\ AuditTrail \\ auditTrail\\ walletEnrolmentValidationMessage \\ Max255Text \\ DNS \\ Message associated with the validation of the card enrollment into a digital wallet 260526112000 \\ AuditTrail \\ auditTrail\\ acsAuthenticationDateTime \\ ISODateTime \\ DNS \\ Date and time of the transaction authentication 260526112200 \\ AuditTrail \\ auditTrail\\ deviceTechnicalName \\ Max255Text \\ DNS \\ Technical name of the device 260526120800 \\ Transaction \\ sinisterData\\ mobileDeviceStolen \\ TrueFalseIndicator \\ DNS \\ Client indicated that their mobile phone was stolen 260526121000 \\ Transaction \\ sinisterData\\ simSwapIndicator \\ TrueFalseIndicator \\ DNS \\ Indicates whether a recent SIM swap has been detected or reported as part of the incident 260526121200 \\ Transaction \\ sinisterData\\ recentPortabilityIndicator \\ TrueFalseIndicator \\ DNS \\ Indicates whether a recent mobile number portability has been detected or reported as part of the incident 260526121400 \\ Transaction \\ sinisterData\\ eSimIndicator \\ TrueFalseIndicator \\ DNS \\ Indicates whether the customer’s device uses an eSIM at the time of the incident 260526130000 \\ AuditTrail \\ auditTrail \\ authenticationEnrolmentChannel \\ AuthenticationEnrolmentChannelCodeset \\ DNS \\ Indicates the channel through which the customer’s authentication device enrollment was performed 260526130500 \\ Environment \\ terminal \\ deviceUniqueIdentifier \\ Max64AlphaNumericText \\ DNS \\ Technical identifier of the device, enabling its unique identification within the system 260526131600 \\ AuditTrail \\ auditTrail \\ isPaymentWallet \\ TrueFalseIndicator \\ DNS \\ Indicates whether this wallet corresponds to the one used for the payment associated with the transaction 260526131700 \\ Edition \\ editionParameters \\ mailVariant \\ Max2Text \\ DNS \\ Defines the letter variant to be generated and allows adapting the layout and document subject 260422171100 \\ Transaction \\ originalTransactionData \\ initialThreeDsProtocolVersion \\ Max2NumericText \\ DNS \\ 3DS protocol major version \\ RSB119_0046_ p1 \\ 119-0046-p1 \\ 059-0046-p1 \\ 056-0046-p1 | F18: BK-9914
A19: 21.14 | B19: G.HARAGHI | C19: 46162 | D19: MOPasserel | E19: Modification des attributs: 260304141000 \\ Transaction \\ transactionDetails \\ extendedAuthorisationIndicator \\ Exact4NumericText \\ DNS \\ Indicator “Extended Authorization” ==> 260304141000 \\ Transaction \\ transactionDetails \\ extendedAuthorisationIndicator \\ Exact1AlphaNumericText \\ DNS \\ Indicator “Extended Authorization” 260304141700 \\ Transaction \\ transactionDetails \\ maximumClearingDate \\ Exact1AlphaNumericText \\ DNS \\ Clearing deadline \\ 112_0083 ==> 260304141700 \\ Transaction \\ transactionDetails \\ maximumClearingDate \\ Exact4NumericText \\ DNS \\ Clearing deadline \\ 112_0083 | F19: BK-9907
A20: 21.14 | B20: G.HARAGHI | C20: 46162 | D20: Emission | E20: Modification des attributs: 260518101800 // Environment // cardFee // standardTariffCode // Max70Text // DNS // Code defining a standard tariff ==> 260518101800 // Environment // cardTariff // standardTariffCode // Max70Text // DNS // Code defining a standard tariff 260518102200 // Environment // cardFee // negotiatedTariffCode // Max70Text // DNS // Code defining a negotiated tariff ==> 260518102200 // Environment // cardTariff // negotiatedTariffCode // Max70Text // DNS // Code defining a negotiated tariff 260518102400 // Environment // cardFee // negociatedTariffStartDate // ISODate // DNS // Start date of the period of a negotiated tariff ==> 260518102400 // Environment // cardTariff // negociatedTariffStartDate // ISODate // DNS // Start date of the period of a negotiated tariff 260518102600 // Environment // cardFee // negociatedTariffEndDate // ISODate // DNS // End date of the period of a negotiated tariff ==> 260518102600 // Environment // cardTariff // negociatedTariffEndDate // ISODate // DNS // End date of the period of a negotiated tariff 260518103000 // Environment // cardFee // minimumFee // FeeAmountType // DNS // Minimum fee applied for the calculation of a card fee ==> 260518103000 // Environment // cardTariff // minimumFee // FeeAmountType // DNS // Minimum fee applied for the calculation of a card fee 260518103200 // Environment // cardFee // maximumFee // FeeAmountType // DNS // Maximum fee applied for the calculation of a card fee ==> 260518103200 // Environment // cardTariff // maximumFee // FeeAmountType // DNS // Maximum fee applied for the calculation of a card fee 260518103400 // Environment // cardFee // tariffRate // PercentageRate // DNS // Rate applied on the base amount ==> 260518103400 // Environment // cardTariff // tariffRate // PercentageRate // DNS // Rate applied on the base amount 260518103600 // Environment // cardFee // tariffFixedAmount // FeeAmountType // DNS // Fixed amount applied for the calculation of a card fee ==> 260518103600 // Environment // cardTariff // tariffFixedAmount // FeeAmountType // DNS // Fixed amount applied for the calculation of a card fee 260518105700 // Environment // cardFee // discountRate // FeeAmountType // DNS // Discount applied on the standard tariff ==> 260518105700 // Environment // cardTariff // discountRate // FeeAmountType // DNS // Discount applied on the standard tariff 260424190700 // Environment // cardFee // calculationMethod // CardFeeCalculationMethodCodeset // DNS // Method used to calculate the card fee ==> 260424190700 // Environment // cardTariff // calculationMethod // CardFeeCalculationMethodCodeset // DNS // Method used to calculate the card fee | F20: BK-9903(Commentaire Enguerran)
A21: 21.14 | B21: G.HARAGHI | C21: 46161 | D21: Acquisition | E21: Modification des attributs: 250528104004 \\ Transaction \\ transactionDetails \\ clearingDate \\ ISODate \\ DNS \\ Expected Date of Clearing ==> 250528104004 \\ Transaction \\ transactionDetails \\ clearingDateTime \\ ISODateTime \\ DNS \\ Expected Date of Clearing 260423174500 \\ Transaction \\ transactionDetails \\ clearingSettlementDate \\ ISODate \\ DNS \\ Clearing Settlement Date calculated by the Pre-Clearing Service. ==> 260423174500 \\ Transaction \\ transactionDetails \\ clearingSettlementDateTime \\ ISODateTime \\ DNS \\ Clearing Settlement Date calculated by the Pre-Clearing Service. | F21: BK-9902
A22: 21.14 | B22: G.HARAGHI | C22: 46161 | D22: Transverse | E22: Modification des attributs: 260324180000 // Transaction // transactionDetails // msgReceivedDateTime // ISODateTime // DNS // // Date Time EO solution has received a question ==> 260324180000 // Transaction // transactionDetails // msgReceivedDateTime // ISODateTime // DNS // // Date Time the processor has received a question 260324180100 // Transaction // transactionDetails // msgSentDateTime // ISODateTime // DNS // // Date Time EO solution has sent a response ==> 260324180100 // Transaction // transactionDetails // msgSentDateTime // ISODateTime // DNS // // Date Time the processor has sent a response 260324180300 // Transaction // transactionDetails // msgReceivedFromIssuerDateTime // ISODateTime // DNS // // Date Time EO solution has received a response from Issuer ==> 260324180300 // Transaction // transactionDetails // msgReceivedFromIssuerDateTime // ISODateTime // DNS // // Date Time the processor has received a response from Issuer 260324180400 // Transaction // transactionDetails // msgSentToIssuerDateTime // ISODateTime // DNS // // Date Time EO solution has sent a question to Issuer ==> 260324180400 // Transaction // transactionDetails // msgSentToIssuerDateTime // ISODateTime // DNS // // Date Time the processor has sent a question to Issuer | F22: Message de Luc
A23: 21.14 | B23: G.HARAGHI | C23: 46161 | D23: Acquisition | E23: Création de l'attribut: 260519101000 \\ Context \\ transactionContext \\ clearingRoute \\ ClearingRouteCodeset \\ DNS \\ Identify the transaction clearing route (INTRA or SCHEME). Création du codeSet ClearingRouteCodeset: ClearingRouteCodeset \\ Exact4Text \\ INTR \\ INTRA ClearingRouteCodeset \\ Exact4Text \\ SCHE \\ SCHEME | F23: BK-9858
A24: 21.14 | B24: G.HARAGHI | C24: 46161 | D24: Acquisition | E24: Création de l'attribut: 260519100200 // Context // transactionContext // qualifScheme // QualifSchemeCodeset // DNS // Scheme identification done by qualification. Création du codeSet QualifSchemeCodeset: QualifSchemeCodeset \\ Exact4Text \\ CBFR \\ CB QualifSchemeCodeset \\ Exact4Text \\ MACD \\ MasterCard QualifSchemeCodeset \\ Exact4Text \\ VISA \\ VISA | F24: BK-9858
... A48: 21.13 | B48: B. Porcher | C48: 46141 | D48: Contestation | E48: Modification de l'attribut "distributedAmount" devient "disputedAmount" 260422142800 / Transaction / disputeData / disputedAmount / AmountType / DNS / / Amount of the transaction related to the dispute | F48: BK-9877
A49: 21.12 | B49: B. Porcher | C49: 46140 | D49: Acquisition | E49: Création du codeset QualificationBrandCodeset / Exact4Text / CBFR / CB QualificationBrandCodeset / Exact4Text / VISA / VISA QualificationBrandCodeset / Exact4Text / VPAY / VISA VPAY QualificationBrandCodeset / Exact4Text / VELC / VISA ELECTRON QualificationBrandCodeset / Exact4Text / MACD / MASTERCARD QualificationBrandCodeset / Exact4Text / MAES / MAESTRO QualificationBrandCodeset / Exact4Text / DISC / DISCOVER QualificationBrandCodeset / Exact4Text / UPIC / UPI CHINA QualificationBrandCodeset / Exact4Text / JCB0 / JCB QualificationBrandCodeset / Exact4Text / AMEX / AMEX QualificationBrandCodeset / Exact4Text / UNKN / Unknown
A50: 21.12 | B50: B. Porcher | C50: 46140 | D50: Acquisition | E50: Création de 2 attributs 260428104900 / Transaction / transactionDetails / qualifCardBrand / QualificationBrandCodeset / DNS / / Brand defined by qualification. 260428105000 / Transaction / transactionDetails / clearingNetwork / NetworkCodeset / DNS / / Network for clearing - Scheme
A51: 21.12 | B51: B. Porcher | C51: 46140 | D51: Emission | E51: Modification d'attribut 250528140504 / Transaction / transactionDetails / feesAmountPayable / AmountType / DNS / / Fees Amount Payable devient 250528140504 / Transaction / transactionDetails / payableFeeAmount / FeeAmountType / DNS / / Payable Fee Amount
A52: 21.12 | B52: B. Porcher | C52: 46136 | D52: Emission | E52: Création des codeset pour les attributs de cardFee CardFeeNegotiationNatureCodeset // Exact4Text // DISC // Negotiated price with a discount CardFeeNegotiationNatureCodeset // Exact4Text // EXPT // Negotiated price with an explicit tariff CardFeeNegotiationNatureCodeset // Exact4Text // STRD // Standard price (no negotiation) CardFeeExemptionReasonCodeset // Exact4Text // PERD // Fee exemption for the period CardFeeExemptionReasonCodeset // Exact4Text // PRCG // Pricing fee exemption CardFeeCalculationMethodCodeset // Exact4Text // EXTL // External price CardFeeCalculationMethodCodeset // Exact4Text // FIXD // Fixed amount CardFeeCalculationMethodCodeset // Exact4Text // FREE // Free price CardFeeCalculationMethodCodeset // Exact4Text // UNIT // Unitary price CardFeeCalculationMethodCodeset // Exact4Text // PROP // Proportional price CardFeeCalculationMethodCodeset // Exact4Text // UNPR // Unitary and proportional price CardFeePartialPeriodCodeset // Exact4Text // FULL // The period is fully charged CardFeePartialPeriodCodeset // Exact4Text // FREE // The period is free CardFeePartialPeriodCodeset // Exact4Text // PRTP // Pro rata temporis over the period applied on the fee | F52: BK-9873
A53: 21.12 | B53: B. Porcher | C53: 46136 | D53: Emission | E53: Création d'un objet cardFee et d'une série d'attributs dans le cadre du nouveau contrat Iss-CMS26_001 "Billing card events" 260424190000 / Environment / cardFee / cardFeeId / Max36IdentifierText / DNS / / Unique identifier of the card fee 260424190100 / Environment / cardFee / creationDateTime / ISODateTime / DNS / / Creation date and time of the card fee 260424190200 / Environment / cardFee / referenceDate / ISODate / DNS / / Reference date of the card fee 260424190300 / Environment / cardFee / payableAmount / FeeAmountType / DNS / / Payable card fee amount 260424190400 / Environment / cardFee / negotiationNature / CardFeeNegotiationNatureCodeset / DNS / / Card fee negotiation conditions 260424190500 / Environment / cardFee / exemptionReason / CardFeeExemptionReasonCodeset / DNS / / Reason for a card fee exemption (zero amount) 260424190600 / Environment / cardFee / settlementDate / ISODate / DNS / / Settlement date of the card fee 260424190700 / Environment / cardFee / calculationMethod / CardFeeCalculationMethodCodeset / DNS / / Method used to calculate the card fee 260424190800 / Environment / cardFee / standardAmount / FeeAmountType / DNS / / Standard amount to apply for a card fee 260424190900 / Environment / cardFee / baseAmount / AmountType / DNS / / Base amount used for the calculation of a card fee 260424191000 / Environment / cardFee / standardRate / PercentageRate / DNS / / Standard rate to apply for a card fee 260424191100 / Environment / cardFee / periodStartDate / ISODate / DNS / / Start date of the period of a recurring card fee 260424191200 / Environment / cardFee / periodEndDate / ISODate / DNS / / End date of the period of a recurring card fee 260424191300 / Environment / cardFee / firstPeriodCalculationCode / CardFeePartialPeriodCodeset / DNS / / Code indicating the calculation mode of the first period of a recurring card fee 260424191400 / Environment / cardFee / lastPeriodCalculationCode / CardFeePartialPeriodCodeset / DNS / / Code indicating the calculation mode of the last period of a recurring card fee | F53: BK-9873
A54: 21.12 | B54: B. Porcher | C54: 46135 | D54: Acquisition | E54: Création d'un attribut clearingSettlementDate 260423174500 / Transaction / transactionDetails / clearingSettlementDate / ISODate / DNS / / Clearing Settlement Date calculated by P2SPen | F54: BK-9837
A55: 21.12 | B55: B. Porcher | C55: 46135 | D55: Acquisition | E55: Ajout des valeurs suivantes au codest CardholderPresenceCodeset CardholderPresenceCodeset / Exact4Text / VADS / Vad Sale | F55: BK-9863
A56: 21.12 | B56: B. Porcher | C56: 46135 | D56: Acquisition | E56: Ajout des valeurs suivantes au codest DigitalWalletNameCodeset DigitalWalletNameCodeset / Exact4Text / PAYL / 04 PAYL (CB2AF 1.6.4 & 1.6.5 et plus après) DigitalWalletNameCodeset / Exact4Text / VPME / 02 V.ME (CB2AF 1.5.0 et plus à partir de 1.6.0) DigitalWalletNameCodeset / Exact4Text / MPAS / 03 Masterpass (ex PPOL, jusqu'à 1.6.3 et plus après) | F56: BK-9825
A57: 21.12 | B57: B. Porcher | C57: 46135 | D57: Contestation | E57: Création des attributs suivants : 260423103400 / Context / claimData / receiptsNumber / Max6NumericText / DNS / / Number of receipts covered by the claim. 260423103500 / Transaction / claimData / saleDate / ISODate / DNS / / Sale Date 260423103600 / Edition / editionParameters / recourseRequestNature / MainServiceCodeset / DNS / / amicable recourse request nature 260423103700 / Transaction / claimData / caseAdvancementCode / CaseAdvancementCodeset / DNS / / Case Advancement Code | F57: BK-9867
A58: 21.12 | B58: B. Porcher | C58: 46135 | D58: Contestation | E58: Modification de Codeset Ajout de la valeur UNKN au codeset CardholderAuthenticationMethodCodeset | F58: BK-9805
A59: 21.12 | B59: B. Porcher | C59: 46134 | D59: Acquisition | E59: Création de l'attribut suivant : 260422150000 / Transaction / remittanceData / mostRecentTransactionDateTime / ISODateTime / DNS / / Most recent transaction of a remittance | F59: BK-9862
A60: 21.12 | B60: B. Porcher | C60: 46134 | D60: Contestation | E60: Ajout de 2 nouvelles valeurs à CaseAdvancementCodeset TRTD : Treated CONS : Constituted | F60: BK-9861
A61: 21.12 | B61: B. Porcher | C61: 46134 | D61: Contestation | E61: Modification du libelle quie devient Reopenning date Time (perd le Last) 251027112302 / Transaction / disputeData / reopeningDateTime / ISODateTime / DNS / / Reopening date time | F61: BK-9857
A62: 21.12 | B62: B. Porcher | C62: 46134 | D62: Contestation | E62: Modification de l'attribut de claimDataId devient claimCaseId 250528103500 / Transaction / claimData / claimCaseId / Exact16AlphaNumericText / DNS / / Claim case reference | F62: BK-9857
A63: 21.12 | B63: B. Porcher | C63: 46134 | D63: Contestation | E63: Création des attributs suivants : 260422141600 / Edition / editionParameters / previousLetterDate / ISODate / DNS / / Claim date 260422141700 / Context / claimData / additionnalData / AdditionalDataType / DNS / / Number of debit receipts 260422141800 / Edition / editionParameters / emailLetterhead / EmailAddressType / DNS / / Number of credit receipts 260422141900 / Edition / editionParameters / letterObject / Max200Text / DNS / / Amount to reverse 260422142000 / Edition / editionParameters / chargebackReasonTitleFieldName / Max50Text / DNS / / Amount to reprocess 260422142100 / Edition / editionParameters / conclusionContent / Max500Text / DNS / / starting date for statement 260422142200 / Edition / editionParameters / finalDateReceipt / ISODate / DNS / / ending date for statement 260422142300 / Transaction / claimData / caseAdvancementLevel / Max2NumericText / DNS / / Case Advancement level 260422142400 / Transaction / claimData / statusUpdateDateTime / ISODateTime / DNS / / Update date time of the status 260422142500 / Transaction / claimData / taskAdvancement / Max255Text / DNS / / Task Advancement 260422142600 / Transaction / claimData / totalAmount / AmountType / DNS / / Total amount of transactions in the claim file 260422142700 / Edition / editionParameters / mailRequestDateTime / ISODateTime / DNS / / Letter request date time 260422142800 / Transaction / disputeData / distributedAmount / AmountType / DNS / / Amount of the transaction related to the dispute 260422142900 / Context / executionContractFinancialParameters / contractRetrievalMethod / Max1Text / DNS / / Contract Retrieval Method 260422143000 / Transaction / transactionDetails / vrolBundleCaseReference / Max35AlphaNumericText / DNS / / VISA Resolve Bundle case reference | F63: BK-9857
...

Sheet MON_MSG
A1: Référence | B1: Segment | C1: Object | D1: Attribute | E1: Type | F1: Libellé | G1: Description | H1: Obligatoire | I1: Répétable | J1: Liste de valeurs du codeset | K1: Ancien Flux | L1: Ancien Nom | M1: Ancien Format | N1: TLP | O1: Autor | P1: Capture | Q1: Precomp | R1: Compens | S1: Litiges | T1: MàJ | U1: Obsolete
A2: 241112000000 | U2: =IF(VLOOKUP($A2,DICO_Complet!A:R,9,FALSE)<>0,VLOOKUP($A2,DICO_Complet!A:R,9,FALSE),"")
A3: 241112000001 | U3: =IF(VLOOKUP($A3,DICO_Complet!A:R,9,FALSE)<>0,VLOOKUP($A3,DICO_Complet!A:R,9,FALSE),"")
A4: 241112000003 | U4: =IF(VLOOKUP($A4,DICO_Complet!A:R,9,FALSE)<>0,VLOOKUP($A4,DICO_Complet!A:R,9,FALSE),"")
A5: 241112000004 | U5: =IF(VLOOKUP($A5,DICO_Complet!A:R,9,FALSE)<>0,VLOOKUP($A5,DICO_Complet!A:R,9,FALSE),"")
A6: 241112000002 | U6: =IF(VLOOKUP($A6,DICO_Complet!A:R,9,FALSE)<>0,VLOOKUP($A6,DICO_Complet!A:R,9,FALSE),"")
A7: 250331114316 | U7: =IF(VLOOKUP($A7,DICO_Complet!A:R,9,FALSE)<>0,VLOOKUP($A7,DICO_Complet!A:R,9,FALSE),"")
A8: 250528104041 | U8: =IF(VLOOKUP($A8,DICO_Complet!A:R,9,FALSE)<>0,VLOOKUP($A8,DICO_Complet!A:R,9,FALSE),"")
A9: 250717102622 | U9: =IF(VLOOKUP($A9,DICO_Complet!A:R,9,FALSE)<>0,VLOOKUP($A9,DICO_Complet!A:R,9,FALSE),"")
A10: 250717102624 | U10: =IF(VLOOKUP($A10,DICO_Complet!A:R,9,FALSE)<>0,VLOOKUP($A10,DICO_Complet!A:R,9,FALSE),"")
A11: 250717102623 | U11: =IF(VLOOKUP($A11,DICO_Complet!A:R,9,FALSE)<>0,VLOOKUP($A11,DICO_Complet!A:R,9,FALSE),"")
A12: 250723172700 | U12: =IF(VLOOKUP($A12,DICO_Complet!A:R,9,FALSE)<>0,VLOOKUP($A12,DICO_Complet!A:R,9,FALSE),"")
A13: 250717102602 | U13: =IF(VLOOKUP($A13,DICO_Complet!A:R,9,FALSE)<>0,VLOOKUP($A13,DICO_Complet!A:R,9,FALSE),"")
... A1833: 260608100200 | U1833: =IF(VLOOKUP($A1833,DICO_Complet!A:R,9,FALSE)<>0,VLOOKUP($A1833,DICO_Complet!A:R,9,FALSE),"")

Sheet MSG_Export
B1: De MON_MSG | C1: Champs reportés de DICO_COMPLET | K1: Champs reportés de MON_MSG | N1: Champs reportés de DICO_COMPLET
A2: Référence | B2: O/N | C2: Segment Message | D2: Object | E2: Attribute | F2: Type | G2: Sensitivty | H2: Colonne2 | I2: Obsolete | J2: Libellé | K2: Description fonctionnelle | L2: Obligatoire | M2: Repetable | N2: CIFO | O2: CBAE | P2: CB2AF | Q2: CB2A | R2: VISA | S2: MCD | T2: Mainframe | U2: .
A3: 241112000000 | B3: =IF(ISNA(VLOOKUP(Tableau161920[[#This Row],[Référence]],MON_MSG!A:B,2,FALSE)),"N",IF($I3="Obsolete","N","O")) -> O | C3: =VLOOKUP($A3,DICO_Complet!A:R,3,FALSE) -> ApiResponse | D3: =VLOOKUP($A3,DICO_Complet!A:R,4,FALSE) -> error | E3: =VLOOKUP($A3,DICO_Complet!A:R,5,FALSE) -> code | F3: =VLOOKUP($A3,DICO_Complet!A:R,6,FALSE) -> Max20Text | G3: =VLOOKUP($A3,DICO_Complet!A:R,7,FALSE) -> DNS | H3: =VLOOKUP($A3,DICO_Complet!A:R,8,FALSE) -> 0 | I3: =IF(VLOOKUP($A3,DICO_Complet!A:R,9,FALSE)<>0,VLOOKUP($A3,DICO_Complet!A:R,9,FALSE),"") | J3: =VLOOKUP($A3,DICO_Complet!A:R,10,FALSE) -> Error code | K3: =IF(OR(ISNA(VLOOKUP(Tableau161920[[#This Row],[Référence]],MON_MSG!A:H,7,FALSE)),ISBLANK(VLOOKUP(Tableau161920[[#This Row],[Référence]],MON_MSG!A:H,7,FALSE))),"",VLOOKUP(Tableau161920[[#This Row],[Référence]],MON_MSG!A:H,7,FALSE)) | L3: =IF(OR(ISNA(VLOOKUP(Tableau161920[[#This Row],[Référence]],MON_MSG!A:I,8,FALSE)),ISBLANK(VLOOKUP(Tableau161920[[#This Row],[Référence]],MON_MSG!A:I,8,FALSE))),"",VLOOKUP(Tableau161920[[#This Row],[Référence]],MON_MSG!A:I,8,FALSE)) | M3: =IF(OR(ISNA(VLOOKUP(Tableau161920[[#This Row],[Référence]],MON_MSG!A:J,9,FALSE)),ISBLANK(VLOOKUP(Tableau161920[[#This Row],[Référence]],MON_MSG!A:J,9,FALSE))),"",VLOOKUP(Tableau161920[[#This Row],[Référence]],MON_MSG!A:J,9,FALSE)) | N3: =IF(VLOOKUP($A3,DICO_Complet!A:R,12,FALSE)=0,"",VLOOKUP($A3,DICO_Complet!A:R,12,FALSE)) | O3: =IF(VLOOKUP($A3,DICO_Complet!A:R,13,FALSE)=0,"",VLOOKUP($A3,DICO_Complet!A:R,13,FALSE)) | P3: =IF(VLOOKUP($A3,DICO_Complet!A:R,14,FALSE)=0,"",VLOOKUP($A3,DICO_Complet!A:R,14,FALSE)) | Q3: =IF(VLOOKUP($A3,DICO_Complet!A:R,15,FALSE)=0,"",VLOOKUP($A3,DICO_Complet!A:R,15,FALSE)) | R3: =IF(VLOOKUP($A3,DICO_Complet!A:R,16,FALSE)=0,"",VLOOKUP($A3,DICO_Complet!A:R,16,FALSE)) | S3: =IF(VLOOKUP($A3,DICO_Complet!A:R,17,FALSE)=0,"",VLOOKUP($A3,DICO_Complet!A:R,17,FALSE)) | T3: =IF(VLOOKUP($A3,DICO_Complet!A:R,18,FALSE)=0,"",VLOOKUP($A3,DICO_Complet!A:R,18,FALSE))
A4: 241112000001 | B4: =IF(ISNA(VLOOKUP(Tableau161920[[#This Row],[Référence]],MON_MSG!A:B,2,FALSE)),"N",IF($I4="Obsolete","N","O")) -> O | C4: =VLOOKUP($A4,DICO_Complet!A:R,3,FALSE) -> ApiResponse | D4: =VLOOKUP($A4,DICO_Complet!A:R,4,FALSE) -> error | E4: =VLOOKUP($A4,DICO_Complet!A:R,5,FALSE) -> developerText | F4: =VLOOKUP($A4,DICO_Complet!A:R,6,FALSE) -> Max70Text | G4: =VLOOKUP($A4,DICO_Complet!A:R,7,FALSE) -> DNS | H4: =VLOOKUP($A4,DICO_Complet!A:R,8,FALSE) -> 0 | I4: =IF(VLOOKUP($A4,DICO_Complet!A:R,9,FALSE)<>0,VLOOKUP($A4,DICO_Complet!A:R,9,FALSE),"") | J4: =VLOOKUP($A4,DICO_Complet!A:R,10,FALSE) -> Explains possible reason(s) of the error, and possible corrections | K4: =IF(OR(ISNA(VLOOKUP(Tableau161920[[#This Row],[Référence]],MON_MSG!A:H,7,FALSE)),ISBLANK(VLOOKUP(Tableau161920[[#This Row],[Référence]],MON_MSG!A:H,7,FALSE))),"",VLOOKUP(Tableau161920[[#This Row],[Référence]],MON_MSG!A:H,7,FALSE)) | L4: =IF(OR(ISNA(VLOOKUP(Tableau161920[[#This Row],[Référence]],MON_MSG!A:I,8,FALSE)),ISBLANK(VLOOKUP(Tableau161920[[#This Row],[Référence]],MON_MSG!A:I,8,FALSE))),"",VLOOKUP(Tableau161920[[#This Row],[Référence]],MON_MSG!A:I,8,FALSE)) | M4: =IF(OR(ISNA(VLOOKUP(Tableau161920[[#This Row],[Référence]],MON_MSG!A:J,9,FALSE)),ISBLANK(VLOOKUP(Tableau161920[[#This Row],[Référence]],MON_MSG!A:J,9,FALSE))),"",VLOOKUP(Tableau161920[[#This Row],[Référence]],MON_MSG!A:J,9,FALSE)) | N4: =IF(VLOOKUP($A4,DICO_Complet!A:R,12,FALSE)=0,"",VLOOKUP($A4,DICO_Complet!A:R,12,FALSE)) | O4: =IF(VLOOKUP($A4,DICO_Complet!A:R,13,FALSE)=0,"",VLOOKUP($A4,DICO_Complet!A:R,13,FALSE)) | P4: =IF(VLOOKUP($A4,DICO_Complet!A:R,14,FALSE)=0,"",VLOOKUP($A4,DICO_Complet!A:R,14,FALSE)) | Q4: =IF(VLOOKUP($A4,DICO_Complet!A:R,15,FALSE)=0,"",VLOOKUP($A4,DICO_Complet!A:R,15,FALSE)) | R4: =IF(VLOOKUP($A4,DICO_Complet!A:R,16,FALSE)=0,"",VLOOKUP($A4,DICO_Complet!A:R,16,FALSE)) | S4: =IF(VLOOKUP($A4,DICO_Complet!A:R,17,FALSE)=0,"",VLOOKUP($A4,DICO_Complet!A:R,17,FALSE)) | T4: =IF(VLOOKUP($A4,DICO_Complet!A:R,18,FALSE)=0,"",VLOOKUP($A4,DICO_Complet!A:R,18,FALSE))
A5: 241112000003 | B5: =IF(ISNA(VLOOKUP(Tableau161920[[#This Row],[Référence]],MON_MSG!A:B,2,FALSE)),"N",IF($I5="Obsolete","N","O")) -> O | C5: =VLOOKUP($A5,DICO_Complet!A:R,3,FALSE) -> ApiResponse | D5: =VLOOKUP($A5,DICO_Complet!A:R,4,FALSE) -> error | E5: =VLOOKUP($A5,DICO_Complet!A:R,5,FALSE) -> moreInfo | F5: =VLOOKUP($A5,DICO_Complet!A:R,6,FALSE) -> Max256Text | G5: =VLOOKUP($A5,DICO_Complet!A:R,7,FALSE) -> DNS | H5: =VLOOKUP($A5,DICO_Complet!A:R,8,FALSE) -> 0 | I5: =IF(VLOOKUP($A5,DICO_Complet!A:R,9,FALSE)<>0,VLOOKUP($A5,DICO_Complet!A:R,9,FALSE),"") | J5: =VLOOKUP($A5,DICO_Complet!A:R,10,FALSE) -> URI to documents | K5: =IF(OR(ISNA(VLOOKUP(Tableau161920[[#This Row],[Référence]],MON_MSG!A:H,7,FALSE)),ISBLANK(VLOOKUP(Tableau161920[[#This Row],[Référence]],MON_MSG!A:H,7,FALSE))),"",VLOOKUP(Tableau161920[[#This Row],[Référence]],MON_MSG!A:H,7,FALSE)) | L5: =IF(OR(ISNA(VLOOKUP(Tableau161920[[#This Row],[Référence]],MON_MSG!A:I,8,FALSE)),ISBLANK(VLOOKUP(Tableau161920[[#This Row],[Référence]],MON_MSG!A:I,8,FALSE))),"",VLOOKUP(Tableau161920[[#This Row],[Référence]],MON_MSG!A:I,8,FALSE)) | M5: =IF(OR(ISNA(VLOOKUP(Tableau161920[[#This Row],[Référence]],MON_MSG!A:J,9,FALSE)),ISBLANK(VLOOKUP(Tableau161920[[#This Row],[Référence]],MON_MSG!A:J,9,FALSE))),"",VLOOKUP(Tableau161920[[#This Row],[Référence]],MON_MSG!A:J,9,FALSE)) | N5: =IF(VLOOKUP($A5,DICO_Complet!A:R,12,FALSE)=0,"",VLOOKUP($A5,DICO_Complet!A:R,12,FALSE)) | O5: =IF(VLOOKUP($A5,DICO_Complet!A:R,13,FALSE)=0,"",VLOOKUP($A5,DICO_Complet!A:R,13,FALSE)) | P5: =IF(VLOOKUP($A5,DICO_Complet!A:R,14,FALSE)=0,"",VLOOKUP($A5,DICO_Complet!A:R,14,FALSE)) | Q5: =IF(VLOOKUP($A5,DICO_Complet!A:R,15,FALSE)=0,"",VLOOKUP($A5,DICO_Complet!A:R,15,FALSE)) | R5: =IF(VLOOKUP($A5,DICO_Complet!A:R,16,FALSE)=0,"",VLOOKUP($A5,DICO_Complet!A:R,16,FALSE)) | S5: =IF(VLOOKUP($A5,DICO_Complet!A:R,17,FALSE)=0,"",VLOOKUP($A5,DICO_Complet!A:R,17,FALSE)) | T5: =IF(VLOOKUP($A5,DICO_Complet!A:R,18,FALSE)=0,"",VLOOKUP($A5,DICO_Complet!A:R,18,FALSE))
A6: 241112000004 | B6: =IF(ISNA(VLOOKUP(Tableau161920[[#This Row],[Référence]],MON_MSG!A:B,2,FALSE)),"N",IF($I6="Obsolete","N","O")) -> O | C6: =VLOOKUP($A6,DICO_Complet!A:R,3,FALSE) -> ApiResponse | D6: =VLOOKUP($A6,DICO_Complet!A:R,4,FALSE) -> error | E6: =VLOOKUP($A6,DICO_Complet!A:R,5,FALSE) -> text | F6: =VLOOKUP($A6,DICO_Complet!A:R,6,FALSE) -> Max40Text | G6: =VLOOKUP($A6,DICO_Complet!A:R,7,FALSE) -> DNS | H6: =VLOOKUP($A6,DICO_Complet!A:R,8,FALSE) -> 0 | I6: =IF(VLOOKUP($A6,DICO_Complet!A:R,9,FALSE)<>0,VLOOKUP($A6,DICO_Complet!A:R,9,FALSE),"") | J6: =VLOOKUP($A6,DICO_Complet!A:R,10,FALSE) -> short text that explains the error in a language that is useful for the end-user of the service | K6: =IF(OR(ISNA(VLOOKUP(Tableau161920[[#This Row],[Référence]],MON_MSG!A:H,7,FALSE)),ISBLANK(VLOOKUP(Tableau161920[[#This Row],[Référence]],MON_MSG!A:H,7,FALSE))),"",VLOOKUP(Tableau161920[[#This Row],[Référence]],MON_MSG!A:H,7,FALSE)) | L6: =IF(OR(ISNA(VLOOKUP(Tableau161920[[#This Row],[Référence]],MON_MSG!A:I,8,FALSE)),ISBLANK(VLOOKUP(Tableau161920[[#This Row],[Référence]],MON_MSG!A:I,8,FALSE))),"",VLOOKUP(Tableau161920[[#This Row],[Référence]],MON_MSG!A:I,8,FALSE)) | M6: =IF(OR(ISNA(VLOOKUP(Tableau161920[[#This Row],[Référence]],MON_MSG!A:J,9,FALSE)),ISBLANK(VLOOKUP(Tableau161920[[#This Row],[Référence]],MON_MSG!A:J,9,FALSE))),"",VLOOKUP(Tableau161920[[#This Row],[Référence]],MON_MSG!A:J,9,FALSE)) | N6: =IF(VLOOKUP($A6,DICO_Complet!A:R,12,FALSE)=0,"",VLOOKUP($A6,DICO_Complet!A:R,12,FALSE)) | O6: =IF(VLOOKUP($A6,DICO_Complet!A:R,13,FALSE)=0,"",VLOOKUP($A6,DICO_Complet!A:R,13,FALSE)) | P6: =IF(VLOOKUP($A6,DICO_Complet!A:R,14,FALSE)=0,"",VLOOKUP($A6,DICO_Complet!A:R,14,FALSE)) | Q6: =IF(VLOOKUP($A6,DICO_Complet!A:R,15,FALSE)=0,"",VLOOKUP($A6,DICO_Complet!A:R,15,FALSE)) | R6: =IF(VLOOKUP($A6,DICO_Complet!A:R,16,FALSE)=0,"",VLOOKUP($A6,DICO_Complet!A:R,16,FALSE)) | S6: =IF(VLOOKUP($A6,DICO_Complet!A:R,17,FALSE)=0,"",VLOOKUP($A6,DICO_Complet!A:R,17,FALSE)) | T6: =IF(VLOOKUP($A6,DICO_Complet!A:R,18,FALSE)=0,"",VLOOKUP($A6,DICO_Complet!A:R,18,FALSE))
A7: 241112000002 | B7: =IF(ISNA(VLOOKUP(Tableau161920[[#This Row],[Référence]],MON_MSG!A:B,2,FALSE)),"N",IF($I7="Obsolete","N","O")) -> O | C7: =VLOOKUP($A7,DICO_Complet!A:R,3,FALSE) -> ApiResponse | D7: =VLOOKUP($A7,DICO_Complet!A:R,4,FALSE) -> httpStatus | E7: =VLOOKUP($A7,DICO_Complet!A:R,5,FALSE) -> httpCode | F7: =VLOOKUP($A7,DICO_Complet!A:R,6,FALSE) -> Exact3NumericText | G7: =VLOOKUP($A7,DICO_Complet!A:R,7,FALSE) -> DNS | H7: =VLOOKUP($A7,DICO_Complet!A:R,8,FALSE) -> 0 | I7: =IF(VLOOKUP($A7,DICO_Complet!A:R,9,FALSE)<>0,VLOOKUP($A7,DICO_Complet!A:R,9,FALSE),"") | J7: =VLOOKUP($A7,DICO_Complet!A:R,10,FALSE) -> Status code http | K7: =IF(OR(ISNA(VLOOKUP(Tableau161920[[#This Row],[Référence]],MON_MSG!A:H,7,FALSE)),ISBLANK(VLOOKUP(Tableau161920[[#This Row],[Référence]],MON_MSG!A:H,7,FALSE))),"",VLOOKUP(Tableau161920[[#This Row],[Référence]],MON_MSG!A:H,7,FALSE)) | L7: =IF(OR(ISNA(VLOOKUP(Tableau161920[[#This Row],[Référence]],MON_MSG!A:I,8,FALSE)),ISBLANK(VLOOKUP(Tableau161920[[#This Row],[Référence]],MON_MSG!A:I,8,FALSE))),"",VLOOKUP(Tableau161920[[#This Row],[Référence]],MON_MSG!A:I,8,FALSE)) | M7: =IF(OR(ISNA(VLOOKUP(Tableau161920[[#This Row],[Référence]],MON_MSG!A:J,9,FALSE)),ISBLANK(VLOOKUP(Tableau161920[[#This Row],[Référence]],MON_MSG!A:J,9,FALSE))),"",VLOOKUP(Tableau161920[[#This Row],[Référence]],MON_MSG!A:J,9,FALSE)) | N7: =IF(VLOOKUP($A7,DICO_Complet!A:R,12,FALSE)=0,"",VLOOKUP($A7,DICO_Complet!A:R,12,FALSE)) | O7: =IF(VLOOKUP($A7,DICO_Complet!A:R,13,FALSE)=0,"",VLOOKUP($A7,DICO_Complet!A:R,13,FALSE)) | P7: =IF(VLOOKUP($A7,DICO_Complet!A:R,14,FALSE)=0,"",VLOOKUP($A7,DICO_Complet!A:R,14,FALSE)) | Q7: =IF(VLOOKUP($A7,DICO_Complet!A:R,15,FALSE)=0,"",VLOOKUP($A7,DICO_Complet!A:R,15,FALSE)) | R7: =IF(VLOOKUP($A7,DICO_Complet!A:R,16,FALSE)=0,"",VLOOKUP($A7,DICO_Complet!A:R,16,FALSE)) | S7: =IF(VLOOKUP($A7,DICO_Complet!A:R,17,FALSE)=0,"",VLOOKUP($A7,DICO_Complet!A:R,17,FALSE)) | T7: =IF(VLOOKUP($A7,DICO_Complet!A:R,18,FALSE)=0,"",VLOOKUP($A7,DICO_Complet!A:R,18,FALSE))
A8: 250331114316 | B8: =IF(ISNA(VLOOKUP(Tableau161920[[#This Row],[Référence]],MON_MSG!A:B,2,FALSE)),"N",IF($I8="Obsolete","N","O")) -> O | C8: =VLOOKUP($A8,DICO_Complet!A:R,3,FALSE) -> ApiResponse | D8: =VLOOKUP($A8,DICO_Complet!A:R,4,FALSE) -> httpStatus | E8: =VLOOKUP($A8,DICO_Complet!A:R,5,FALSE) -> requestId | F8: =VLOOKUP($A8,DICO_Complet!A:R,6,FALSE) -> Max36NumericText | G8: =VLOOKUP($A8,DICO_Complet!A:R,7,FALSE) -> DNS | H8: =VLOOKUP($A8,DICO_Complet!A:R,8,FALSE) -> 0 | I8: =IF(VLOOKUP($A8,DICO_Complet!A:R,9,FALSE)<>0,VLOOKUP($A8,DICO_Complet!A:R,9,FALSE),"") | J8: =VLOOKUP($A8,DICO_Complet!A:R,10,FALSE) -> Unique ID of API response | K8: =IF(OR(ISNA(VLOOKUP(Tableau161920[[#This Row],[Référence]],MON_MSG!A:H,7,FALSE)),ISBLANK(VLOOKUP(Tableau161920[[#This Row],[Référence]],MON_MSG!A:H,7,FALSE))),"",VLOOKUP(Tableau161920[[#This Row],[Référence]],MON_MSG!A:H,7,FALSE)) | L8: =IF(OR(ISNA(VLOOKUP(Tableau161920[[#This Row],[Référence]],MON_MSG!A:I,8,FALSE)),ISBLANK(VLOOKUP(Tableau161920[[#This Row],[Référence]],MON_MSG!A:I,8,FALSE))),"",VLOOKUP(Tableau161920[[#This Row],[Référence]],MON_MSG!A:I,8,FALSE)) | M8: =IF(OR(ISNA(VLOOKUP(Tableau161920[[#This Row],[Référence]],MON_MSG!A:J,9,FALSE)),ISBLANK(VLOOKUP(Tableau161920[[#This Row],[Référence]],MON_MSG!A:J,9,FALSE))),"",VLOOKUP(Tableau161920[[#This Row],[Référence]],MON_MSG!A:J,9,FALSE)) | N8: =IF(VLOOKUP($A8,DICO_Complet!A:R,12,FALSE)=0,"",VLOOKUP($A8,DICO_Complet!A:R,12,FALSE)) | O8: =IF(VLOOKUP($A8,DICO_Complet!A:R,13,FALSE)=0,"",VLOOKUP($A8,DICO_Complet!A:R,13,FALSE)) | P8: =IF(VLOOKUP($A8,DICO_Complet!A:R,14,FALSE)=0,"",VLOOKUP($A8,DICO_Complet!A:R,14,FALSE)) | Q8: =IF(VLOOKUP($A8,DICO_Complet!A:R,15,FALSE)=0,"",VLOOKUP($A8,DICO_Complet!A:R,15,FALSE)) | R8: =IF(VLOOKUP($A8,DICO_Complet!A:R,16,FALSE)=0,"",VLOOKUP($A8,DICO_Complet!A:R,16,FALSE)) | S8: =IF(VLOOKUP($A8,DICO_Complet!A:R,17,FALSE)=0,"",VLOOKUP($A8,DICO_Complet!A:R,17,FALSE)) | T8: =IF(VLOOKUP($A8,DICO_Complet!A:R,18,FALSE)=0,"",VLOOKUP($A8,DICO_Complet!A:R,18,FALSE))
A9: 250528104041 | B9: =IF(ISNA(VLOOKUP(Tableau161920[[#This Row],[Référence]],MON_MSG!A:B,2,FALSE)),"N",IF($I9="Obsolete","N","O")) -> O | C9: =VLOOKUP($A9,DICO_Complet!A:R,3,FALSE) -> AuditTrail | D9: =VLOOKUP($A9,DICO_Complet!A:R,4,FALSE) -> auditTrail | E9: =VLOOKUP($A9,DICO_Complet!A:R,5,FALSE) -> alertDateTime | F9: =VLOOKUP($A9,DICO_Complet!A:R,6,FALSE) -> ISODateTime | G9: =VLOOKUP($A9,DICO_Complet!A:R,7,FALSE) -> DNS | H9: =VLOOKUP($A9,DICO_Complet!A:R,8,FALSE) -> 0 | I9: =IF(VLOOKUP($A9,DICO_Complet!A:R,9,FALSE)<>0,VLOOKUP($A9,DICO_Complet!A:R,9,FALSE),"") | J9: =VLOOKUP($A9,DICO_Complet!A:R,10,FALSE) -> Alert date time | K9: =IF(OR(ISNA(VLOOKUP(Tableau161920[[#This Row],[Référence]],MON_MSG!A:H,7,FALSE)),ISBLANK(VLOOKUP(Tableau161920[[#This Row],[Référence]],MON_MSG!A:H,7,FALSE))),"",VLOOKUP(Tableau161920[[#This Row],[Référence]],MON_MSG!A:H,7,FALSE)) | L9: =IF(OR(ISNA(VLOOKUP(Tableau161920[[#This Row],[Référence]],MON_MSG!A:I,8,FALSE)),ISBLANK(VLOOKUP(Tableau161920[[#This Row],[Référence]],MON_MSG!A:I,8,FALSE))),"",VLOOKUP(Tableau161920[[#This Row],[Référence]],MON_MSG!A:I,8,FALSE)) | M9: =IF(OR(ISNA(VLOOKUP(Tableau161920[[#This Row],[Référence]],MON_MSG!A:J,9,FALSE)),ISBLANK(VLOOKUP(Tableau161920[[#This Row],[Référence]],MON_MSG!A:J,9,FALSE))),"",VLOOKUP(Tableau161920[[#This Row],[Référence]],MON_MSG!A:J,9,FALSE)) | N9: =IF(VLOOKUP($A9,DICO_Complet!A:R,12,FALSE)=0,"",VLOOKUP($A9,DICO_Complet!A:R,12,FALSE)) | O9: =IF(VLOOKUP($A9,DICO_Complet!A:R,13,FALSE)=0,"",VLOOKUP($A9,DICO_Complet!A:R,13,FALSE)) | P9: =IF(VLOOKUP($A9,DICO_Complet!A:R,14,FALSE)=0,"",VLOOKUP($A9,DICO_Complet!A:R,14,FALSE)) | Q9: =IF(VLOOKUP($A9,DICO_Complet!A:R,15,FALSE)=0,"",VLOOKUP($A9,DICO_Complet!A:R,15,FALSE)) | R9: =IF(VLOOKUP($A9,DICO_Complet!A:R,16,FALSE)=0,"",VLOOKUP($A9,DICO_Complet!A:R,16,FALSE)) | S9: =IF(VLOOKUP($A9,DICO_Complet!A:R,17,FALSE)=0,"",VLOOKUP($A9,DICO_Complet!A:R,17,FALSE)) | T9: =IF(VLOOKUP($A9,DICO_Complet!A:R,18,FALSE)=0,"",VLOOKUP($A9,DICO_Complet!A:R,18,FALSE))
A10: 250717102622 | B10: =IF(ISNA(VLOOKUP(Tableau161920[[#This Row],[Référence]],MON_MSG!A:B,2,FALSE)),"N",IF($I10="Obsolete","N","O")) -> O | C10: =VLOOKUP($A10,DICO_Complet!A:R,3,FALSE) -> AuditTrail | D10: =VLOOKUP($A10,DICO_Complet!A:R,4,FALSE) -> auditTrail | E10: =VLOOKUP($A10,DICO_Complet!A:R,5,FALSE) -> alertMessage | F10: =VLOOKUP($A10,DICO_Complet!A:R,6,FALSE) -> Max255Text | G10: =VLOOKUP($A10,DICO_Complet!A:R,7,FALSE) -> DNS | H10: =VLOOKUP($A10,DICO_Complet!A:R,8,FALSE) -> 0 | I10: =IF(VLOOKUP($A10,DICO_Complet!A:R,9,FALSE)<>0,VLOOKUP($A10,DICO_Complet!A:R,9,FALSE),"") | J10: =VLOOKUP($A10,DICO_Complet!A:R,10,FALSE) -> Message content | K10: =IF(OR(ISNA(VLOOKUP(Tableau161920[[#This Row],[Référence]],MON_MSG!A:H,7,FALSE)),ISBLANK(VLOOKUP(Tableau161920[[#This Row],[Référence]],MON_MSG!A:H,7,FALSE))),"",VLOOKUP(Tableau161920[[#This Row],[Référence]],MON_MSG!A:H,7,FALSE)) | L10: =IF(OR(ISNA(VLOOKUP(Tableau161920[[#This Row],[Référence]],MON_MSG!A:I,8,FALSE)),ISBLANK(VLOOKUP(Tableau161920[[#This Row],[Référence]],MON_MSG!A:I,8,FALSE))),"",VLOOKUP(Tableau161920[[#This Row],[Référence]],MON_MSG!A:I,8,FALSE)) | M10: =IF(OR(ISNA(VLOOKUP(Tableau161920[[#This Row],[Référence]],MON_MSG!A:J,9,FALSE)),ISBLANK(VLOOKUP(Tableau161920[[#This Row],[Référence]],MON_MSG!A:J,9,FALSE))),"",VLOOKUP(Tableau161920[[#This Row],[Référence]],MON_MSG!A:J,9,FALSE)) | N10: =IF(VLOOKUP($A10,DICO_Complet!A:R,12,FALSE)=0,"",VLOOKUP($A10,DICO_Complet!A:R,12,FALSE)) | O10: =IF(VLOOKUP($A10,DICO_Complet!A:R,13,FALSE)=0,"",VLOOKUP($A10,DICO_Complet!A:R,13,FALSE)) | P10: =IF(VLOOKUP($A10,DICO_Complet!A:R,14,FALSE)=0,"",VLOOKUP($A10,DICO_Complet!A:R,14,FALSE)) | Q10: =IF(VLOOKUP($A10,DICO_Complet!A:R,15,FALSE)=0,"",VLOOKUP($A10,DICO_Complet!A:R,15,FALSE)) | R10: =IF(VLOOKUP($A10,DICO_Complet!A:R,16,FALSE)=0,"",VLOOKUP($A10,DICO_Complet!A:R,16,FALSE)) | S10: =IF(VLOOKUP($A10,DICO_Complet!A:R,17,FALSE)=0,"",VLOOKUP($A10,DICO_Complet!A:R,17,FALSE)) | T10: =IF(VLOOKUP($A10,DICO_Complet!A:R,18,FALSE)=0,"",VLOOKUP($A10,DICO_Complet!A:R,18,FALSE))
A11: 250717102624 | B11: =IF(ISNA(VLOOKUP(Tableau161920[[#This Row],[Référence]],MON_MSG!A:B,2,FALSE)),"N",IF($I11="Obsolete","N","O")) -> O | C11: =VLOOKUP($A11,DICO_Complet!A:R,3,FALSE) -> AuditTrail | D11: =VLOOKUP($A11,DICO_Complet!A:R,4,FALSE) -> auditTrail | E11: =VLOOKUP($A11,DICO_Complet!A:R,5,FALSE) -> alertRecipientEmailAddress | F11: =VLOOKUP($A11,DICO_Complet!A:R,6,FALSE) -> EmailAddressType | G11: =VLOOKUP($A11,DICO_Complet!A:R,7,FALSE) -> DSP | H11: =VLOOKUP($A11,DICO_Complet!A:R,8,FALSE) -> 0 | I11: =IF(VLOOKUP($A11,DICO_Complet!A:R,9,FALSE)<>0,VLOOKUP($A11,DICO_Complet!A:R,9,FALSE),"") | J11: =VLOOKUP($A11,DICO_Complet!A:R,10,FALSE) -> email that received the message | K11: =IF(OR(ISNA(VLOOKUP(Tableau161920[[#This Row],[Référence]],MON_MSG!A:H,7,FALSE)),ISBLANK(VLOOKUP(Tableau161920[[#This Row],[Référence]],MON_MSG!A:H,7,FALSE))),"",VLOOKUP(Tableau161920[[#This Row],[Référence]],MON_MSG!A:H,7,FALSE)) | L11: =IF(OR(ISNA(VLOOKUP(Tableau161920[[#This Row],[Référence]],MON_MSG!A:I,8,FALSE)),ISBLANK(VLOOKUP(Tableau161920[[#This Row],[Référence]],MON_MSG!A:I,8,FALSE))),"",VLOOKUP(Tableau161920[[#This Row],[Référence]],MON_MSG!A:I,8,FALSE)) | M11: =IF(OR(ISNA(VLOOKUP(Tableau161920[[#This Row],[Référence]],MON_MSG!A:J,9,FALSE)),ISBLANK(VLOOKUP(Tableau161920[[#This Row],[Référence]],MON_MSG!A:J,9,FALSE))),"",VLOOKUP(Tableau161920[[#This Row],[Référence]],MON_MSG!A:J,9,FALSE)) | N11: =IF(VLOOKUP($A11,DICO_Complet!A:R,12,FALSE)=0,"",VLOOKUP($A11,DICO_Complet!A:R,12,FALSE)) | O11: =IF(VLOOKUP($A11,DICO_Complet!A:R,13,FALSE)=0,"",VLOOKUP($A11,DICO_Complet!A:R,13,FALSE)) | P11: =IF(VLOOKUP($A11,DICO_Complet!A:R,14,FALSE)=0,"",VLOOKUP($A11,DICO_Complet!A:R,14,FALSE)) | Q11: =IF(VLOOKUP($A11,DICO_Complet!A:R,15,FALSE)=0,"",VLOOKUP($A11,DICO_Complet!A:R,15,FALSE)) | R11: =IF(VLOOKUP($A11,DICO_Complet!A:R,16,FALSE)=0,"",VLOOKUP($A11,DICO_Complet!A:R,16,FALSE)) | S11: =IF(VLOOKUP($A11,DICO_Complet!A:R,17,FALSE)=0,"",VLOOKUP($A11,DICO_Complet!A:R,17,FALSE)) | T11: =IF(VLOOKUP($A11,DICO_Complet!A:R,18,FALSE)=0,"",VLOOKUP($A11,DICO_Complet!A:R,18,FALSE))
A12: 250717102623 | B12: =IF(ISNA(VLOOKUP(Tableau161920[[#This Row],[Référence]],MON_MSG!A:B,2,FALSE)),"N",IF($I12="Obsolete","N","O")) -> O | C12: =VLOOKUP($A12,DICO_Complet!A:R,3,FALSE) -> AuditTrail | D12: =VLOOKUP($A12,DICO_Complet!A:R,4,FALSE) -> auditTrail | E12: =VLOOKUP($A12,DICO_Complet!A:R,5,FALSE) -> alertRecipientPhoneNumber | F12: =VLOOKUP($A12,DICO_Complet!A:R,6,FALSE) -> PhoneNumberText | G12: =VLOOKUP($A12,DICO_Complet!A:R,7,FALSE) -> DSP | H12: =VLOOKUP($A12,DICO_Complet!A:R,8,FALSE) -> 0 | I12: =IF(VLOOKUP($A12,DICO_Complet!A:R,9,FALSE)<>0,VLOOKUP($A12,DICO_Complet!A:R,9,FALSE),"") | J12: =VLOOKUP($A12,DICO_Complet!A:R,10,FALSE) -> Phone that received the message | K12: =IF(OR(ISNA(VLOOKUP(Tableau161920[[#This Row],[Référence]],MON_MSG!A:H,7,FALSE)),ISBLANK(VLOOKUP(Tableau161920[[#This Row],[Référence]],MON_MSG!A:H,7,FALSE))),"",VLOOKUP(Tableau161920[[#This Row],[Référence]],MON_MSG!A:H,7,FALSE)) | L12: =IF(OR(ISNA(VLOOKUP(Tableau161920[[#This Row],[Référence]],MON_MSG!A:I,8,FALSE)),ISBLANK(VLOOKUP(Tableau161920[[#This Row],[Référence]],MON_MSG!A:I,8,FALSE))),"",VLOOKUP(Tableau161920[[#This Row],[Référence]],MON_MSG!A:I,8,FALSE)) | M12: =IF(OR(ISNA(VLOOKUP(Tableau161920[[#This Row],[Référence]],MON_MSG!A:J,9,FALSE)),ISBLANK(VLOOKUP(Tableau161920[[#This Row],[Référence]],MON_MSG!A:J,9,FALSE))),"",VLOOKUP(Tableau161920[[#This Row],[Référence]],MON_MSG!A:J,9,FALSE)) | N12: =IF(VLOOKUP($A12,DICO_Complet!A:R,12,FALSE)=0,"",VLOOKUP($A12,DICO_Complet!A:R,12,FALSE)) | O12: =IF(VLOOKUP($A12,DICO_Complet!A:R,13,FALSE)=0,"",VLOOKUP($A12,DICO_Complet!A:R,13,FALSE)) | P12: =IF(VLOOKUP($A12,DICO_Complet!A:R,14,FALSE)=0,"",VLOOKUP($A12,DICO_Complet!A:R,14,FALSE)) | Q12: =IF(VLOOKUP($A12,DICO_Complet!A:R,15,FALSE)=0,"",VLOOKUP($A12,DICO_Complet!A:R,15,FALSE)) | R12: =IF(VLOOKUP($A12,DICO_Complet!A:R,16,FALSE)=0,"",VLOOKUP($A12,DICO_Complet!A:R,16,FALSE)) | S12: =IF(VLOOKUP($A12,DICO_Complet!A:R,17,FALSE)=0,"",VLOOKUP($A12,DICO_Complet!A:R,17,FALSE)) | T12: =IF(VLOOKUP($A12,DICO_Complet!A:R,18,FALSE)=0,"",VLOOKUP($A12,DICO_Complet!A:R,18,FALSE))
A13: 250723172700 | B13: =IF(ISNA(VLOOKUP(Tableau161920[[#This Row],[Référence]],MON_MSG!A:B,2,FALSE)),"N",IF($I13="Obsolete","N","O")) -> O | C13: =VLOOKUP($A13,DICO_Complet!A:R,3,FALSE) -> AuditTrail | D13: =VLOOKUP($A13,DICO_Complet!A:R,4,FALSE) -> auditTrail | E13: =VLOOKUP($A13,DICO_Complet!A:R,5,FALSE) -> auditPhoneNumber | F13: =VLOOKUP($A13,DICO_Complet!A:R,6,FALSE) -> PhoneNumberType | G13: =VLOOKUP($A13,DICO_Complet!A:R,7,FALSE) -> DSP | H13: =VLOOKUP($A13,DICO_Complet!A:R,8,FALSE) -> 0 | I13: =IF(VLOOKUP($A13,DICO_Complet!A:R,9,FALSE)<>0,VLOOKUP($A13,DICO_Complet!A:R,9,FALSE),"") | J13: =VLOOKUP($A13,DICO_Complet!A:R,10,FALSE) -> Phone number with usage and security tag | K13: =IF(OR(ISNA(VLOOKUP(Tableau161920[[#This Row],[Référence]],MON_MSG!A:H,7,FALSE)),ISBLANK(VLOOKUP(Tableau161920[[#This Row],[Référence]],MON_MSG!A:H,7,FALSE))),"",VLOOKUP(Tableau161920[[#This Row],[Référence]],MON_MSG!A:H,7,FALSE)) | L13: =IF(OR(ISNA(VLOOKUP(Tableau161920[[#This Row],[Référence]],MON_MSG!A:I,8,FALSE)),ISBLANK(VLOOKUP(Tableau161920[[#This Row],[Référence]],MON_MSG!A:I,8,FALSE))),"",VLOOKUP(Tableau161920[[#This Row],[Référence]],MON_MSG!A:I,8,FALSE)) | M13: =IF(OR(ISNA(VLOOKUP(Tableau161920[[#This Row],[Référence]],MON_MSG!A:J,9,FALSE)),ISBLANK(VLOOKUP(Tableau161920[[#This Row],[Référence]],MON_MSG!A:J,9,FALSE))),"",VLOOKUP(Tableau161920[[#This Row],[Référence]],MON_MSG!A:J,9,FALSE)) | N13: =IF(VLOOKUP($A13,DICO_Complet!A:R,12,FALSE)=0,"",VLOOKUP($A13,DICO_Complet!A:R,12,FALSE)) | O13: =IF(VLOOKUP($A13,DICO_Complet!A:R,13,FALSE)=0,"",VLOOKUP($A13,DICO_Complet!A:R,13,FALSE)) | P13: =IF(VLOOKUP($A13,DICO_Complet!A:R,14,FALSE)=0,"",VLOOKUP($A13,DICO_Complet!A:R,14,FALSE)) | Q13: =IF(VLOOKUP($A13,DICO_Complet!A:R,15,FALSE)=0,"",VLOOKUP($A13,DICO_Complet!A:R,15,FALSE)) | R13: =IF(VLOOKUP($A13,DICO_Complet!A:R,16,FALSE)=0,"",VLOOKUP($A13,DICO_Complet!A:R,16,FALSE)) | S13: =IF(VLOOKUP($A13,DICO_Complet!A:R,17,FALSE)=0,"",VLOOKUP($A13,DICO_Complet!A:R,17,FALSE)) | T13: =IF(VLOOKUP($A13,DICO_Complet!A:R,18,FALSE)=0,"",VLOOKUP($A13,DICO_Complet!A:R,18,FALSE))
A14: 250717102602 | B14: =IF(ISNA(VLOOKUP(Tableau161920[[#This Row],[Référence]],MON_MSG!A:B,2,FALSE)),"N",IF($I14="Obsolete","N","O")) -> O | C14: =VLOOKUP($A14,DICO_Complet!A:R,3,FALSE) -> AuditTrail | D14: =VLOOKUP($A14,DICO_Complet!A:R,4,FALSE) -> auditTrail | E14: =VLOOKUP($A14,DICO_Complet!A:R,5,FALSE) -> auditTrailId | F14: =VLOOKUP($A14,DICO_Complet!A:R,6,FALSE) -> Max255AlphaNumericText | G14: =VLOOKUP($A14,DICO_Complet!A:R,7,FALSE) -> DNS | H14: =VLOOKUP($A14,DICO_Complet!A:R,8,FALSE) -> 0 | I14: =IF(VLOOKUP($A14,DICO_Complet!A:R,9,FALSE)<>0,VLOOKUP($A14,DICO_Complet!A:R,9,FALSE),"") | J14: =VLOOKUP($A14,DICO_Complet!A:R,10,FALSE) -> Audit trail reference | K14: =IF(OR(ISNA(VLOOKUP(Tableau161920[[#This Row],[Référence]],MON_MSG!A:H,7,FALSE)),ISBLANK(VLOOKUP(Tableau161920[[#This Row],[Référence]],MON_MSG!A:H,7,FALSE))),"",VLOOKUP(Tableau161920[[#This Row],[Référence]],MON_MSG!A:H,7,FALSE)) | L14: =IF(OR(ISNA(VLOOKUP(Tableau161920[[#This Row],[Référence]],MON_MSG!A:I,8,FALSE)),ISBLANK(VLOOKUP(Tableau161920[[#This Row],[Référence]],MON_MSG!A:I,8,FALSE))),"",VLOOKUP(Tableau161920[[#This Row],[Référence]],MON_MSG!A:I,8,FALSE)) | M14: =IF(OR(ISNA(VLOOKUP(Tableau161920[[#This Row],[Référence]],MON_MSG!A:J,9,FALSE)),ISBLANK(VLOOKUP(Tableau161920[[#This Row],[Référence]],MON_MSG!A:J,9,FALSE))),"",VLOOKUP(Tableau161920[[#This Row],[Référence]],MON_MSG!A:J,9,FALSE)) | N14: =IF(VLOOKUP($A14,DICO_Complet!A:R,12,FALSE)=0,"",VLOOKUP($A14,DICO_Complet!A:R,12,FALSE)) | O14: =IF(VLOOKUP($A14,DICO_Complet!A:R,13,FALSE)=0,"",VLOOKUP($A14,DICO_Complet!A:R,13,FALSE)) | P14: =IF(VLOOKUP($A14,DICO_Complet!A:R,14,FALSE)=0,"",VLOOKUP($A14,DICO_Complet!A:R,14,FALSE)) | Q14: =IF(VLOOKUP($A14,DICO_Complet!A:R,15,FALSE)=0,"",VLOOKUP($A14,DICO_Complet!A:R,15,FALSE)) | R14: =IF(VLOOKUP($A14,DICO_Complet!A:R,16,FALSE)=0,"",VLOOKUP($A14,DICO_Complet!A:R,16,FALSE)) | S14: =IF(VLOOKUP($A14,DICO_Complet!A:R,17,FALSE)=0,"",VLOOKUP($A14,DICO_Complet!A:R,17,FALSE)) | T14: =IF(VLOOKUP($A14,DICO_Complet!A:R,18,FALSE)=0,"",VLOOKUP($A14,DICO_Complet!A:R,18,FALSE))
